// try catch

let number = 2
let number2 = 5
let number3 = 10

console.log(number)
console.log(number2)
console.log(number3)


try {
    console.log(number1)

}catch (errror) {
    console.log(`errror al encontrar numero`)
}

